# 异常详解

## 一、概念

异常可以降低错误处理代码的复杂度，如果不使用异常就必须检查特定的错误，并在程序中的很多地方处理它。使用异常则不必在方法调用处进行检查，异常机制能够捕获该错误并且只需要在一个地方（异常处理程序）处理错误。同时区分出正常执行和出问题处理的代码。

## 二、基本异常

异常情景指阻止当前方法或者作用域继续执行的问题。

当抛出异常之后，首先将使用 new 在堆上创建异常对象，然后当前的执行路径被终止，并从当前环境中弹出对异常对象的引用。此时异常处理机制接管程序，并在异常处理程序中来继续执行程序。该异常处理程序任务是将程序从错误状态中恢复，是的程序换一种方式运行或者继续运行。

因为需要使用 new 在堆中创建异常对象，其伴随着存储空间的分配和构造器的调用。所有的标准异常类都有两个构造器：默认构造器和接收字符串参数的构造器；

`throw new NullPointException("this is null");`

使用 new 创建异常对象后，该异常对象的引用将传给 throw，即最终返回一个异常对象，然后退出方法或者作用域。

## 三、捕获异常

监控区域：是一段可能产生异常的代码，并且后面跟着处理这些异常的代码；

### （一）try 块

如果不希望当方法内部抛出异常，或者当方法内部调用其它方法抛出异常的时候结束，则可以在该方法中设置一个 try 块来捕获异常，因为在该块中会「尝试」各种可能尝试异常的方法调用。

### （二）异常处理程序

异常处理程序即处理抛出的异常的地方，每个 catch 子句（异常处理程序）类似于一个接收有且只有一个特殊类型的参数的方法，可以在处理程序内部使用标识符（e1,e2…），类似于方法参数。

异常处理程序必须紧跟 try 块之后，当异常抛出，异常处理机制将复杂搜寻参数与异常类型相匹配的第一个处理程序。

异常处理理论上有两种基本模型：

- 终止模型：即错误非常严重，一旦异常抛出即错误无法挽回，也不能回来继续执行。

- 恢复模型：即异常处理程序工作是修复错误，然后重新尝试调用出问题的方法，并认为第二次能成功。即异常处理完成之后继续执行程序。

  实现方式：遇见错误不能抛出异常，而是调用方法来修正该错误。或者将 try 块放在 while 循环中。

  不推荐使用，因为恢复性的程序需要了解异常抛出地点，导致会包含依赖于抛出位置的非通用性代码，同时抛出地点过多导致维护困难；

## 四、创建自定义异常

自定义异常类必须从已有的异常类继承，编译器会创建默认构造器，并将自动调用基类的默认构造器。一般无需提供带字符串参数的构造器，不常用，如果需要提供则格式如下：

```java
package com.gjxaiou.exception;

public class MyException extends Exception{
    public MyException(){}
    public MyException(String msg){
        // 调用基类构造器
        super(msg);
    }
}
```

使用示例：

```java
package com.gjxaiou.exception;

public class MyException extends Exception {
    public MyException() {
    }

    public MyException(String msg) {
        super(msg);
    }
}


class Demo {
    public static void f() throws MyException {
        System.out.println("has myException");
        throw new MyException();
    }

    public static void g() throws MyException {
        System.out.println("has myException");
        throw new MyException("has param");
    }

    public static void main(String[] args) {
        try {
            f();
        } catch (MyException e) {
            // 调用 Throwable 中声明的 printStackTrace() 方法，其将打印从方法调用处直到异常抛出处的方法调用序列
            // 这里信息会被输出到标准错误流
            e.printStackTrace();
            // 同上
            e.printStackTrace(System.err);
            // 错误信息被自动捕捉和显示到输出中，但是其可能会被重定向。
            e.printStackTrace(System.out);
        }
    }
}
```

## 五、异常说明

可以通过跟在形式参数列表后面的异常说明，告知调用方可能抛出的异常类型，其也属于方法声明的一部分；

实现方式：通过 throws 后面跟随所有潜在的异常类型列表，使用逗号隔开；但是当异常是继承自 RuntimeException，则可以在没有异常说明的情况下被抛出，即方法声明中可以不写该异常类型；

即要不处理异常，要不在异常说明中表明该方法将产生异常。当然可以声明方法将抛出异常，但实际上不抛出，即为异常占个位置，当定义抽象基类和接口时推荐，这样派生类或接口实现后期就能抛出这些预先声明的异常，而不用修改方法声明；

以上能在编译时被强制检查的异常称为「被检查的异常」。

## 六、捕获所有异常

通常在 catch 的最后使用 `catch(Exception e)` 来捕获所有异常，因为 Exception 是与编程有关的所有异常类的基类，所以虽然其自身不会含有太多具体信息但是可以调用其基类 Throwable 继承的方法：

```java
// 获取详细信息
String getMessage();
// 使用本地语言表示的详细信息
String getLocalizedMessage();
```

如果想要打印 Throwable 的描述信息和 Throwable 的调用栈轨迹，其中调用栈显示了「把你带到异常抛出地点」的方法调用序列。可以使用：

```java
// 输出到标准错误
void printStackTrace();
// 可以选择要输出的流
void printStackTrace(PrintStream s);
void printStackTrace(PrintStreamOrWriter s);
void printStackTrace(PrintWriter s);
```

同时 `Throwable fillInStackTrace()` 用于记录在 Throwable 对象的内部记录栈帧的当前状态，主要用于程序重新抛出错误或者异常；

当然可以调研 Throwable 的基类 Object 中的 `getClass()`、`getNames()`、`getSimpleNames()` 方法；

### (一)栈轨迹

`getStackTrace()` 方法返回一个由栈轨迹中的元素所构成的数组，其中每个元素都表示栈中的一帧，元素 0 是栈顶元素，同时是调用序列中的最后一个方法调用（该 Throwable 被创建和抛出之外）。数据中最后一个元素和栈底是调用序列中的第一个方法调用。

```java
package com.gjxaiou.exception;

public class PrintMessage {
    static void f(){
        try {
            throw new Exception();
        }catch (Exception e){
            for (StackTraceElement ste : e.getStackTrace()) {
                System.out.println(ste);
            }
        }
    }
    
    static void g(){
        f();
    }

    public static void main(String[] args) {
        g();
    }
}
```

输出结果为：

```java
com.gjxaiou.exception.PrintMessage.f(PrintMessage.java:6)
com.gjxaiou.exception.PrintMessage.g(PrintMessage.java:15)
com.gjxaiou.exception.PrintMessage.main(PrintMessage.java:19)
```

### (二)重新抛出异常

重新抛出异常就是将异常抛给上一级环境中的异常处理程序，同一个 try 块的后续 catch 子句被忽略，因为已经在 catch 中获取了当前异常对象的引用，所以异常对象的所有信息得以保存，即上一级环境的异常处理程序可以获取该异常对象中的所有信息。

重新抛出时，`printStackTrace()` 只显示原来异常抛出点的调用栈信息，而不是重新抛出的信息，可以使用 `fillInStackTrace()` 返回的 Throwable 对象，其会将当前调用栈信息填入原有异常对象。即调用 fillInStackTrace() 的哪一行成了异常的新发生地。

同时当捕获异常之后抛出另一种异常，则效果类似 `fillInStackTrace()`，即原有的异常发生点的信息会丢失，只剩与新的抛出点有关的信息；

```java
package com.gjxaiou.exception;

public class ReThrowException {
    static void f() throws Exception{
        throw new Exception("from f()");
    }

    static void g() throws Exception{
        try {
            f();
        }catch (Exception e){
        e.printStackTrace();

        throw e;
        }
    }

    static void h() throws Exception{
        try {
            f();
        }catch (Exception e){
            e.printStackTrace();

            throw (Exception) e.fillInStackTrace();
        }
    }

    public static void main(String[] args) {
        try {
            g();
        }catch (Exception e){
            e.printStackTrace();
        }
        System.out.println("-----------------------");

        try {
            h();
        }catch (Exception e){
            e.printStackTrace();
        }
    }
}
```

执行结果为：

```java
java.lang.Exception: from f()
	at com.gjxaiou.exception.ReThrowException.f(ReThrowException.java:5)
	at com.gjxaiou.exception.ReThrowException.g(ReThrowException.java:10)
	at com.gjxaiou.exception.ReThrowException.main(ReThrowException.java:30)
java.lang.Exception: from f()
	at com.gjxaiou.exception.ReThrowException.f(ReThrowException.java:5)
	at com.gjxaiou.exception.ReThrowException.g(ReThrowException.java:10)
	at com.gjxaiou.exception.ReThrowException.main(ReThrowException.java:30)
java.lang.Exception: from f()
	at com.gjxaiou.exception.ReThrowException.f(ReThrowException.java:5)
	at com.gjxaiou.exception.ReThrowException.h(ReThrowException.java:20)
	at com.gjxaiou.exception.ReThrowException.main(ReThrowException.java:37)
java.lang.Exception: from f()
	at com.gjxaiou.exception.ReThrowException.h(ReThrowException.java:24)
	at com.gjxaiou.exception.ReThrowException.main(ReThrowException.java:37)
-----------------------
```

接收和抛出异常不同

```java
package com.gjxaiou.exception;

public class DifferentException {
    public static void f()  throws OneException{
        throw new OneException("f one");
    }

    public static void main(String[] args) {
        try{
            try {
                f();
            }catch (OneException e){
                System.out.println(e.getMessage());
                e.printStackTrace();
                throw new TwoException(e.getMessage());
            }
        }catch (TwoException e){
            System.out.println(e.getMessage());
            e.printStackTrace();
        }
    }
}

class  OneException extends Exception{
    OneException(String s){
        super(s);
    }
}

class TwoException extends Exception{
    TwoException(String s){
        super(s);
    }
}
```

输出为：

```java
f one
f one
com.gjxaiou.exception.OneException: f one
	at com.gjxaiou.exception.DifferentException.f(DifferentException.java:5)
	at com.gjxaiou.exception.DifferentException.main(DifferentException.java:11)
com.gjxaiou.exception.TwoException: f one
	at com.gjxaiou.exception.DifferentException.main(DifferentException.java:15)
```

可见，重新抛出异常之后，原来异常发生处就丢失了，同时因为异常的构造类只能传入 String，所以无法保存堆栈信息；

然后可以将自定义异常的构造器修改一下，传入 Exception 信息，就可以传递堆栈下去了。

```java
package com.gjxaiou.exception;

public class DifferentException {
    public static void f()  throws OneException{
        throw new OneException("f one");
    }

    public static void main(String[] args) {
        try{
            try {
                f();
            }catch (OneException e){
                System.out.println(e.getMessage());
                e.printStackTrace();
                throw new TwoException(e);
            }
        }catch (TwoException e){
            System.out.println(e.getMessage());
            e.printStackTrace();
        }
    }
}

class  OneException extends Exception{
    OneException(String s){
        super(s);
    }
}

class TwoException extends Exception{
    TwoException(Exception s){
        super(s);
    }
}
```

对应的输出结果为：

```java
f one
com.gjxaiou.exception.OneException: f one
com.gjxaiou.exception.OneException: f one
	at com.gjxaiou.exception.DifferentException.f(DifferentException.java:5)
	at com.gjxaiou.exception.DifferentException.main(DifferentException.java:11)
com.gjxaiou.exception.TwoException: com.gjxaiou.exception.OneException: f one
	at com.gjxaiou.exception.DifferentException.main(DifferentException.java:15)
Caused by: com.gjxaiou.exception.OneException: f one
	at com.gjxaiou.exception.DifferentException.f(DifferentException.java:5)
	at com.gjxaiou.exception.DifferentException.main(DifferentException.java:11)
```

### (三)异常链

如果想在捕获一个异常之后抛出另一个异常并保留原有异常信息，则统称为「异常链」。

实现：Throwable 的部分子类（Error/Exception/RuntimeException）在构造器中接收一个 Throwable cause 对象作为参数，该 cause 即表示原始异常，然后通过它可以将原始异常传递给新的异常，使得即是在当前位置创建并抛出新的异常，也能通过该异常链追踪到异常最初发生的位置；

同时如果要实现异常链，需要使用 initCause() 方法而不是构造器；

```java
package com.gjxaiou.exception;

import java.util.ArrayList;
import java.util.List;

public class ExceptionChain {
    public static void f() throws CustomException{
        try {
            List<Integer> list = new ArrayList<>();
            Integer integer = list.get(0);

        }catch (ArrayIndexOutOfBoundsException e){
            CustomException cust = new CustomException();
            cust.initCause(e);
            throw cust;
        }
    }

    public static void main(String[] args) {
        try {
            f();
        }catch (CustomException e){
            e.printStackTrace();
        }
    }
}

class CustomException extends Exception{
}
```

## 七、Java 标准异常

Throwable 类被用来表示任何可以作为异常被抛出的类，其子类分为：

- ERROR：表示编译时和系统错误，一般无需关心；
- Exception：是可以被抛出的基础类型，Java 类库、用户方法和运行时故障都可能抛出；

### RuntimeException

运行时异常会自动被 Java 虚拟机抛出，称之为「不受检查异常」，即该种异常属于错误，会被自动捕捉；即对于该种异常类型，编译器不需要异常说明，其输出直接报告给了 System.err，并且会在程序退出前调用异常的 printStackTrace()。

即只能在代码中忽略 RuntimeException（及其子类）类型的异常，其他异常的处理由编译器强制执行，因为 RuntimeException 本质为编程错误。



## 八、Finally

需要时刻询问自己：如果异常发生，所有东西是否可以正确清理；

无论 try 块中的异常是否抛出，finally 块都会得到执行，通常用于内部回收之外的情况，因为内存回收由垃圾处理器完成。所以 finally 子句一般用于把除内存之外的资源恢复到它们的初始状态时，包括已经打开的文件或者网络链接，图形等等；同统一在 finally 中处理避免了 try 和 catch 中的重复代码，同时可以防止没有捕获的异常（即抛出了）导致没有执行后续处理。**同时 finally 中代码甚至在异常没有被当前的异常处理程序捕获的情况下，异常处理机制也会在跳到更高一层的异常处理程序之前，执行 finally 语句**。

```java
package com.gjxaiou.exception;

public class AlwaysException {
    public static void main(String[] args) {
        try {
            System.out.println("first try");
            try {
                throw new FourException()   ;
            }finally {
                System.out.println("second try-finally");
            }
        }catch (FourException e){
            System.out.println("first try-catch");
        }finally {
            System.out.println("first try-finally");
        }
    }
}

class FourException extends Exception{}

```

执行结果为：

```java
first try
second try-finally
first try-catch
first try-finally
```

当 Java 中的异常不允许我们回到异常抛出地点时，可以将 try 块放在循环中，即建立了一个「程序继续执行之前必须要达到」 的条件，示例如下：

```java
package com.gjxaiou.exception;

public class ForException {
static int count = 0;
    public static void main(String[] args) {
        while (true){
            try{
                if(count++ == 0){
                    throw new ThreeException();
                }
                System.out.println("There has no exception");
            }catch (ThreeException e){
                System.out.println("There has exception");
            }finally {
                System.out.println("this is finally");
                if (count == 2){
                    break;
                }
            }
        }
    }
}

class ThreeException extends  Exception{
}
```

执行结果为：

```java
There has exception
this is finally
There has no exception
this is finally
```

同时，因为 finally 子句总会执行，所以在一个方法中，可以从多个点返回，并且可以保证重要的清理工作仍然会执行：

```java
package com.gjxaiou.exception;

public class ReturnFinally {
    public static String f(){
        try {
            return "this is f()";
        }finally {
            System.out.println("执行 finally");
        }
    }

    public static void main(String[] args) {
        String result = f();
        System.out.println(result);
    }
}
```

执行结果为：

```java
执行 finally
this is f()
```

### (三)异常丢失

```java
package com.gjxaiou.exception;

public class LoseException {
    public void f() throws FirstException{
        throw new FirstException();
    }

    public void g() throws SecondException{
        throw new SecondException();
    }

    public static void main(String[] args) {
        try {
            LoseException le = new LoseException();
            try {
                le.f();
            }finally {
                le.g();
            }
        }catch (Exception e){
            System.out.println(e);
        }
    }
}

class FirstException extends Exception{
    public String toString(){
        return "firstException";
    }
}

class SecondException extends Exception{
    public String toString(){
        return "secondException";
    }
}
```

结果为：

```java
secondException
```

即内部 try 中返回的 firstException 被 finally 子句中的 secondException 替代了，导致异常丢失。

还有一种常见的丢失异常的方式是在 finally 子句中返回：

```java
package com.gjxaiou.exception;

public class SilencerException {
    public static void main(String[] args) {
        try {
            throw new RuntimeException();
        }finally {
            return;
        }
    }
}
```

返回值为空；

## 九、构造器

构造器会将对象设置成安全的初始状态，但是如果构造器中包括其他动作，如打开文件等，因为该动作只有在对象使用完毕并且用户调用了特殊的清理方法之后才能得以清理。如果构造器内抛出异常，则该清理行为无法无法正常工作。同时因为构造器在执行过程中没有执行完成，即该对象的某部分并没有被成功创建，所以不能在 finally 进行清理；

在构造阶段可能会抛出异常并且要求清理的类，最安全的使用方式是使用嵌套的 try 子句：

同时即使在构造器不抛出任何异常也应该使用，原则为：在创建需要清理的对象之后，立即进入 try-finally 语句块；

```java
package com.gjxaiou.exception;

import java.io.BufferedReader;
import java.io.FileNotFoundException;
import java.io.FileReader;
import java.io.IOException;

public class ConstructorException {
    public static void main(String[] args) {
        try {
            // IntputFile 对象如果构造失败，则进入外部 catch 语句，不会调用 dispose 方法
            InputFile in = new InputFile("demo.java");
            // 如果构造成功，则立即创建新的 try 块，保证对象能够被清理，即执行 finally
            try {
                String s;
                while ((s = in.getLine()) != null) {
                    System.out.println(s);
                }
            } catch (Exception e) {
                System.out.println("catch the exception");
                e.printStackTrace();
            } finally {
                in.dispose();
            }
        } catch (Exception e) {
            System.out.println("构造失败");
        }
    }
}


class InputFile {
    private BufferedReader in;

    // InputFile 的构造器
    public InputFile(String name) throws Exception {
        try {
            // 使用传入的文件名称，构建 FileReader，用于构建 BufferedReader 对象
            in = new BufferedReader(new FileReader(name));
        } catch (FileNotFoundException e) {
            System.out.println("找不到文件" + name);
            throw e;
        } catch (Exception e) {
            try {
                in.close();
            } catch (IOException e1) {
                System.out.println("关闭失败");
                throw e1;
            }
        } finally {
            // 这里不能关闭文件，以为可能构造器出问题，其实还没有文件
        }
    }

    public String getLine() {
        String s;
        try {
            s = in.readLine();
        } catch (IOException e) {
            throw new RuntimeException("读取行失败");
        }
        return s;
    }

    public void dispose() {
        try {
            in.close();
        } catch (IOException e) {
            throw new RuntimeException("关闭失败");
        }
    }
}
```

输出结果为：

```java
找不到文件demo.java
构造失败
```

如果 InputFile 构造器失败了，则抛出 FileNotFoundException 异常，对于该异常无需关闭文件，因为文件尚未打开；但是任何其它捕捉异常的 catch 子句必须关闭文件，因为在它们捕捉到异常时，文件已经打开了（如果有其他方法能抛出 FileNotFoundException，则该方法就显得投机取巧了，此时必须把这些方法分别放在不同的 try 块中），同时因为 close 方法也可能抛出异常，所以即使其在另一个 catch 子块中，但还是需要一层 try-catch，即在本地处理完成之后，异常被重新抛出，因为这里是针对构造器而言的，不能让调用方认为这个对象已经创建完毕，可以使用了。

因为我们希望文件在 InputFile 对象的整个生命周期内都处于打开状态，所以不能在 finally 中执行 close 方法来关闭文件，因为如果这样就是每次完成构造器之后都会执行一遍。

同时用户在不再需要 InputFile 对象时候，则必须调用 dispose() 方法来释放 BufferedReader 和 FileReader 对象所占用的系统资源（如文件句柄）。







 







